Workbook

Sheet rawdata
A1: ID | B1: NAME | C1: AGE | D1: JOINED | E1: COMPLETED | F1: AREA | G1: CITY
A2: 22S001 | B2: Rian | C2: 17 | D2: 44563 | E2: 44593 | F2: Beach Road | G2: Chidambaram
A3: 22S002 | B3: Shreshthn | C3: 21 | D3: 44570 | E3: 44612 | F3: Keeranathan | G3: Chidambaram | I3: {=_xlfn._xlws.FILTER(A:G,G:G="Panruti")} -> 22S004 | J3: Zohaann | K3: 19 | L3: 44577 | M3: 44613 | N3: Beach Road | O3: Panruti | Q3: =DAY(D2) -> 2
A4: 22S003 | B4: Aymann | C4: 30 | D4: 44576 | E4: 44628 | F4: Ratchagar Nager | G4: Pondicherry | I4: 22S009 | J4: Aditya | K4: 18 | L4: 44588 | M4: 44633 | N4: Manjakuppam | O4: Panruti | Q4: =DAY(D3) -> 9
A5: 22S004 | B5: Zohaann | C5: 19 | D5: 44577 | E5: 44613 | F5: Beach Road | G5: Panruti | I5: 22S014 | J5: Rudra | K5: 26 | L5: 44607 | M5: 44659 | N5: Saibaba Colony | O5: Panruti | Q5: =DAY(D4) -> 15
A6: 22S005 | B6: Lakshann | C6: 18 | D6: 44578 | E6: 44612 | F6: Vanniyar Palayam | G6: Cuddalore | I6: 22S016 | J6: Shlok | K6: 25 | L6: 44609 | M6: 44662 | N6: Vellapakkam | O6: Panruti | Q6: =DAY(D5) -> 16
A7: 22S006 | B7: Pranitn | C7: 27 | D7: 44578 | E7: 44629 | F7: Keeranathan | G7: Neyveli | I7: 22S018 | J7: Arjun | K7: 16 | L7: 44621 | M7: 44669 | N7: Manjakuppam | O7: Panruti | Q7: =DAY(D6) -> 17
A8: 22S007 | B8: Madhavn | C8: 23 | D8: 44585 | E8: 44639 | F8: Varakalpattu | G8: Cuddalore | I8: 22S027 | J8: Mokshn | K8: 19 | L8: 44643 | M8: 44702 | N8: O.T | O8: Panruti | Q8: =DAY(D7) -> 17
A9: 22S008 | B9: Srihann | C9: 30 | D9: 44586 | E9: 44623 | F9: Devanampattinam | G9: Cuddalore | I9: 22S029 | J9: Tanishn | K9: 17 | L9: 44648 | M9: 44679 | N9: Pattampakkam | O9: Panruti | Q9: =DAY(D8) -> 24
A10: 22S009 | B10: Aditya | C10: 18 | D10: 44588 | E10: 44633 | F10: Manjakuppam | G10: Panruti | I10: 22S037 | J10: Viyaan | K10: 25 | L10: 44669 | M10: 44720 | N10: O.T | O10: Panruti | Q10: =DAY(D9) -> 25
A11: 22S010 | B11: Revaann | C11: 18 | D11: 44589 | E11: 44647 | F11: Pattampakkam | G11: Neyveli | I11: 22S049 | J11: Jayden | K11: 17 | L11: 44706 | M11: 44763 | N11: Vellapakkam | O11: Panruti | Q11: =DAY(D10) -> 27
A12: 22S011 | B12: Chrisn | C12: 30 | D12: 44590 | E12: 44623 | F12: Keeranathan | G12: Cuddalore | I12: 22S055 | J12: Ravin | K12: 20 | L12: 44737 | M12: 44790 | N12: Vellapakkam | O12: Panruti | Q12: =DAY(D11) -> 28
A13: 22S012 | B13: Vedanshn | C13: 21 | D13: 44604 | E13: 44634 | F13: Sowdheshwari Nagar | G13: Cuddalore | I13: 22S079 | J13: Yuvin | K13: 20 | L13: 44833 | M13: 44864 | N13: MGR Nagar | O13: Panruti | Q13: =DAY(D12) -> 29
A14: 22S013 | B14: Kanhan | C14: 22 | D14: 44605 | E14: 44642 | F14: RK Streen | G14: Cuddalore | I14: 22S086 | J14: Saiyamn | K14: 28 | L14: 44864 | M14: 44901 | N14: Varakalpattu | O14: Panruti
A15: 22S014 | B15: Rudra | C15: 26 | D15: 44607 | E15: 44659 | F15: Saibaba Colony | G15: Panruti | I15: 22S090 | J15: Riyaann | K15: 0 | L15: 44868 | M15: 44902 | N15: O.T | O15: Panruti
A16: 22S015 | B16: Aarav | C16: 30 | D16: 44608 | E16: 44642 | F16: Saibaba Colony | G16: Chidambaram | I16: 22S099 | J16: Krishn | K16: 18 | L16: 44908 | M16: 44956 | N16: Chinna Kangananguppam | O16: Panruti
A17: 22S016 | B17: Shlok | C17: 25 | D17: 44609 | E17: 44662 | F17: Vellapakkam | G17: Panruti
A18: 22S017 | B18: Ishaan | C18: 22 | D18: 44620 | E18: 44679 | F18: JJ Nagar | G18: Pondicherry | I18: {=_xlfn._xlws.FILTER(A:G,C:C>=30)} -> ID | J18: NAME | K18: AGE | L18: JOINED | M18: COMPLETED | N18: AREA | O18: CITY
A19: 22S018 | B19: Arjun | C19: 16 | D19: 44621 | E19: 44669 | F19: Manjakuppam | G19: Panruti | I19: 22S003 | J19: Aymann | K19: 30 | L19: 44576 | M19: 44628 | N19: Ratchagar Nager | O19: Pondicherry
A20: 22S019 | B20: Raghav | C20: 18 | D20: 44622 | E20: 44680 | F20: Kalaigner Karunanithi Street | G20: Pondicherry | I20: 22S008 | J20: Srihann | K20: 30 | L20: 44586 | M20: 44623 | N20: Devanampattinam | O20: Cuddalore
A21: 22S020 | B21: Jayn | C21: 24 | D21: 44623 | E21: 44682 | F21: Keeranathan | G21: Neyveli | I21: 22S011 | J21: Chrisn | K21: 30 | L21: 44590 | M21: 44623 | N21: Keeranathan | O21: Cuddalore
A22: 22S021 | B22: Kiaan | C22: 26 | D22: 44624 | E22: 44654 | F22: MK Street | G22: Chidambaram | I22: 22S015 | J22: Aarav | K22: 30 | L22: 44608 | M22: 44642 | N22: Saibaba Colony | O22: Chidambaram
A23: 22S022 | B23: Reyansh | C23: 25 | D23: 44626 | E23: 44681 | F23: Vella Gate | G23: Pondicherry | I23: 22S053 | J23: Shaurya | K23: 30 | L23: 44730 | M23: 44788 | N23: MK Street | O23: Neyveli
A24: 22S023 | B24: Rishaan | C24: 22 | D24: 44632 | E24: 44666 | F24: Beach Road | G24: Neyveli | I24: 22S057 | J24: Yohann | K24: 30 | L24: 44744 | M24: 44793 | N24: Saibaba Colony | O24: Neyveli
A25: 22S024 | B25: Ritvikn | C25: 22 | D25: 44632 | E25: 44665 | F25: Sowdheshwari Nagar | G25: Pondicherry | I25: 22S095 | J25: Viratn | K25: 30 | L25: 44894 | M25: 44947 | N25: RK Streen | O25: Cuddalore
A26: 22S025 | B26: Aviraj | C26: 28 | D26: 44634 | E26: 44683 | F26: Varakalpattu | G26: Cuddalore | I26: 22S100 | J26: Ayaan | K26: 30 | L26: 44923 | M26: 44963 | N26: Purushothaman Street | O26: Neyveli
A27: 22S026 | B27: Ethan | C27: 24 | D27: 44635 | E27: 44679 | F27: Pattampakkam | G27: Pondicherry
A28: 22S027 | B28: Mokshn | C28: 19 | D28: 44643 | E28: 44702 | F28: O.T | G28: Panruti | I28: {=_xlfn._xlws.FILTER(A:G,(G:G="Pondicherry")*(C:C>20))} -> 22S003 | J28: Aymann | K28: 30 | L28: 44576 | M28: 44628 | N28: Ratchagar Nager | O28: Pondicherry
A29: 22S028 | B29: Zayann | C29: 19 | D29: 44646 | E29: 44698 | F29: Purushothaman Street | G29: Pondicherry | I29: 22S017 | J29: Ishaan | K29: 22 | L29: 44620 | M29: 44679 | N29: JJ Nagar | O29: Pondicherry
A30: 22S029 | B30: Tanishn | C30: 17 | D30: 44648 | E30: 44679 | F30: Pattampakkam | G30: Panruti | I30: 22S022 | J30: Reyansh | K30: 25 | L30: 44626 | M30: 44681 | N30: Vella Gate | O30: Pondicherry
A31: 22S030 | B31: Sai | C31: 26 | D31: 44648 | E31: 44697 | F31: Saibaba Colony | G31: Chidambaram | I31: 22S024 | J31: Ritvikn | K31: 22 | L31: 44632 | M31: 44665 | N31: Sowdheshwari Nagar | O31: Pondicherry
A32: 22S031 | B32: Advik | C32: 23 | D32: 44654 | E32: 44703 | F32: Semmandalam | G32: Chidambaram | I32: 22S026 | J32: Ethan | K32: 24 | L32: 44635 | M32: 44679 | N32: Pattampakkam | O32: Pondicherry
A33: 22S032 | B33: Kavin | C33: 16 | D33: 44655 | E33: 44712 | F33: Chinna Pattampakkam | G33: Pondicherry | I33: 22S034 | J33: Ivaan | K33: 29 | L33: 44659 | M33: 44717 | N33: Beach Road | O33: Pondicherry
A34: 22S033 | B34: Anayn | C34: 22 | D34: 44657 | E34: 44701 | F34: Veli Semmandalam | G34: Cuddalore | I34: 22S040 | J34: Pranav | K34: 21 | L34: 44672 | M34: 44717 | N34: Sowdheshwari Nagar | O34: Pondicherry
A35: 22S034 | B35: Ivaan | C35: 29 | D35: 44659 | E35: 44717 | F35: Beach Road | G35: Pondicherry | I35: 22S060 | J35: Krishna | K35: 23 | L35: 44753 | M35: 44805 | N35: JJ Nagar | O35: Pondicherry
A36: 22S035 | B36: Agastya | C36: 20 | D36: 44669 | E36: 44701 | F36: Semmandalam | G36: Neyveli | I36: 22S062 | J36: Aaryan | K36: 24 | L36: 44760 | M36: 44793 | N36: 0 | O36: Pondicherry
A37: 22S036 | B37: Dhakshann | C37: 16 | D37: 44669 | E37: 44705 | F37: MGR Nagar | G37: Neyveli | I37: 22S063 | J37: Dakshn | K37: 28 | L37: 44762 | M37: 44807 | N37: RK Streen | O37: Pondicherry
A38: 22S037 | B38: Viyaan | C38: 25 | D38: 44669 | E38: 44720 | F38: O.T | G38: Panruti | I38: 22S064 | J38: Zionn | K38: 28 | L38: 44764 | M38: 44819 | N38: Periya Kangananguppam | O38: Pondicherry
A39: 22S038 | B39: Parthn | C39: 17 | D39: 44672 | E39: 44718 | F39: Vella Gate | G39: Pondicherry | I39: 22S066 | J39: Priyanshn | K39: 23 | L39: 44773 | M39: 44804 | N39: JJ Nagar | O39: Pondicherry
A40: 22S039 | B40: Aayansh | C40: 18 | D40: 44672 | E40: 44714 | F40: Kalaigner Karunanithi Street | G40: Cuddalore | I40: 22S071 | J40: Advait | K40: 29 | L40: 44798 | M40: 44844 | N40: Chinna Pattampakkam | O40: Pondicherry
...

Sheet lookup
A1: Lookup
A2: V lookup | B2: Column wise | D2: VLOOKUP(A8,rawdata!A$2:G$101,7,0)
A3: H lookup | B3: Row wise
A4: lookup | B4: old version - need sorting before
A5: X lookup | B5: New -both V and H
A7: Vlookup
A8: ID | B8: Name | C8: City | D8: withlock | E8: without lock
A9: 22S004 | B9: =VLOOKUP(A9,rawdata!A:B,2,0) -> Zohaann | C9: =VLOOKUP(A9,rawdata!A$2:G$101,7,0) -> Panruti | D9: =VLOOKUP(A9,rawdata!$A$2:$G$101,3,0) -> 19 | E9: =VLOOKUP(A9,rawdata!A2:B101,2,0) -> Zohaann
A10: 22S009 | B10: =VLOOKUP(A10,rawdata!A:B,2,0) -> Aditya | C10: =VLOOKUP(A10,rawdata!A$2:G$101,7,0) -> Panruti | D10: =VLOOKUP(A10,rawdata!$A$2:$G$101,3,0) -> 18 | E10: =VLOOKUP(A10,rawdata!A3:B102,2,0) -> Aditya
A11: 22S014 | B11: =VLOOKUP(A11,rawdata!A:B,2,0) -> Rudra | C11: =VLOOKUP(A11,rawdata!A$2:G$101,7,0) -> Panruti | D11: =VLOOKUP(A11,rawdata!$A$2:$G$101,3,0) -> 26 | E11: =VLOOKUP(A11,rawdata!A4:B103,2,0) -> Rudra
A12: 22S016 | B12: =VLOOKUP(A12,rawdata!A:B,2,0) -> Shlok | C12: =VLOOKUP(A12,rawdata!A$2:G$101,7,0) -> Panruti | D12: =VLOOKUP(A12,rawdata!$A$2:$G$101,3,0) -> 25 | E12: =VLOOKUP(A12,rawdata!A5:B104,2,0) -> Shlok
A13: 22S018 | B13: =VLOOKUP(A13,rawdata!A:B,2,0) -> Arjun | C13: =VLOOKUP(A13,rawdata!A$2:G$101,7,0) -> Panruti | D13: =VLOOKUP(A13,rawdata!$A$2:$G$101,3,0) -> 16 | E13: =VLOOKUP(A13,rawdata!A6:B105,2,0) -> Arjun
A14: 22S027 | B14: =VLOOKUP(A14,rawdata!A:B,2,0) -> Mokshn | C14: =VLOOKUP(A14,rawdata!A$2:G$101,7,0) -> Panruti | D14: =VLOOKUP(A14,rawdata!$A$2:$G$101,3,0) -> 19 | E14: =VLOOKUP(A14,rawdata!A7:B106,2,0) -> Mokshn
A15: 22S001 | D15: =VLOOKUP(A15,rawdata!$A$2:$G$101,3,0) -> 17 | E15: =VLOOKUP(A15,rawdata!A8:B107,2,0) -> #N/A
A16: H lookup
A17: {=TRANSPOSE(rawdata!A1:G8)} -> ID | B17: 22S001 | C17: 22S002 | D17: 22S003 | E17: 22S004 | F17: 22S005 | G17: 22S006 | H17: 22S007
A18: NAME | B18: Rian | C18: Shreshthn | D18: Aymann | E18: Zohaann | F18: Lakshann | G18: Pranitn | H18: Madhavn
A19: AGE | B19: 17 | C19: 21 | D19: 30 | E19: 19 | F19: 18 | G19: 27 | H19: 23
A20: JOINED | B20: 44563 | C20: 44570 | D20: 44576 | E20: 44577 | F20: 44578 | G20: 44578 | H20: 44585
A21: COMPLETED | B21: 44593 | C21: 44612 | D21: 44628 | E21: 44613 | F21: 44612 | G21: 44629 | H21: 44639
A22: AREA | B22: Beach Road | C22: Keeranathan | D22: Ratchagar Nager | E22: Beach Road | F22: Vanniyar Palayam | G22: Keeranathan | H22: Varakalpattu
A23: CITY | B23: Chidambaram | C23: Chidambaram | D23: Pondicherry | E23: Panruti | F23: Cuddalore | G23: Neyveli | H23: Cuddalore
A25: ID | B25: Name | C25: City
A26: 22S004 | B26: =HLOOKUP(A26,_xlfn.ANCHORARRAY(A$17),2,0) -> Zohaann | C26: =HLOOKUP(A26,_xlfn.ANCHORARRAY(A$17),7,0) -> Panruti
A27: 22S009 | B27: =HLOOKUP(A27,_xlfn.ANCHORARRAY(A$17),2,0) -> #N/A | C27: =HLOOKUP(A27,_xlfn.ANCHORARRAY(A$17),7,0) -> #N/A
A28: 22S014 | B28: =HLOOKUP(A28,_xlfn.ANCHORARRAY(A$17),2,0) -> #N/A | C28: =HLOOKUP(A28,_xlfn.ANCHORARRAY(A$17),7,0) -> #N/A
A29: 22S007 | B29: =HLOOKUP(A29,_xlfn.ANCHORARRAY(A$17),2,0) -> Madhavn | C29: =HLOOKUP(A29,_xlfn.ANCHORARRAY(A$17),7,0) -> Cuddalore
A30: 22S018 | B30: =HLOOKUP(A30,_xlfn.ANCHORARRAY(A$17),2,0) -> #N/A | C30: =HLOOKUP(A30,_xlfn.ANCHORARRAY(A$17),7,0) -> #N/A
A31: 22S027 | B31: =HLOOKUP(A31,_xlfn.ANCHORARRAY(A$17),2,0) -> #N/A | C31: =HLOOKUP(A31,_xlfn.ANCHORARRAY(A$17),7,0) -> #N/A
A33: lookup
A34: lookup | B34: Name | C34: City
A35: 22S004 | B35: =LOOKUP(A35,rawdata!A$1:A$101,rawdata!B$1:B$101) -> Zohaann | C35: =LOOKUP(A35,B$17:H$17,B$23:H$23) -> Panruti | D35: =LOOKUP(A35,A$17:H$17,A$19:H$19) -> 19 | E35: =LOOKUP(A35,17:17,A20:H20) -> 44577
A36: 22S009 | B36: =LOOKUP(A36,rawdata!A$1:A$101,rawdata!B$1:B$101) -> Aditya | C36: =LOOKUP(A36,B$17:H$17,B$23:H$23) -> Cuddalore | D36: =LOOKUP(A36,A$17:H$17,A$19:H$19) -> 23 | E36: =LOOKUP(A36,18:18,A21:H21) -> #N/A
A37: 22S006 | B37: =LOOKUP(A37,rawdata!A$1:A$101,rawdata!B$1:B$101) -> Pranitn | C37: =LOOKUP(A37,B$17:H$17,B$23:H$23) -> Neyveli | D37: =LOOKUP(A37,A$17:H$17,A$19:H$19) -> 27 | E37: =LOOKUP(A37,19:19,A22:H22) -> #N/A
A38: 22S007 | B38: =LOOKUP(A38,rawdata!A$1:A$101,rawdata!B$1:B$101) -> Madhavn | C38: =LOOKUP(A38,B$17:H$17,B$23:H$23) -> Cuddalore | D38: =LOOKUP(A38,A$17:H$17,A$19:H$19) -> 23 | E38: =LOOKUP(A38,20:20,A23:H23) -> #N/A
A39: 22S018 | B39: =LOOKUP(A39,rawdata!A$1:A$101,rawdata!B$1:B$101) -> Arjun | C39: =LOOKUP(A39,B$17:H$17,B$23:H$23) -> Cuddalore | D39: =LOOKUP(A39,A$17:H$17,A$19:H$19) -> 23 | E39: =LOOKUP(A39,21:21,A24:H24) -> #N/A
A40: 22S027 | B40: =LOOKUP(A40,rawdata!A$1:A$101,rawdata!B$1:B$101) -> Mokshn | C40: =LOOKUP(A40,B$17:H$17,B$23:H$23) -> Cuddalore | D40: =LOOKUP(A40,A$17:H$17,A$19:H$19) -> 23 | E40: =LOOKUP(A40,22:22,A25:H25) -> #N/A
A42: xlookup
A43: id | B43: name | C43: city
A44: 22S004 | B44: =_xlfn.XLOOKUP(A44,rawdata!A$2:A$101,rawdata!B$2:B$101,"not found",0,1) -> Zohaann | C44: =_xlfn.XLOOKUP(A44,B$17:H$17,B$23:H$23,"Not found",0,1) -> Panruti | E44: =_xlfn.XLOOKUP(A44,A$17:H$17,A$19:H$19,"not found",0) -> 19 | F44: =_xlfn.XLOOKUP(A44,rawdata!A$2:A$101,rawdata!G$2:G$101,"Not Found",0) -> Panruti | G44: =_xlfn.XLOOKUP(A44,A$17:H$17,A$22:H$22,"Not found",0) -> Beach Road | H44: =_xlfn.XLOOKUP(A44,rawdata!A$2:A$101,rawdata!E$2:E$101,"not found",0) -> 44613
...

Sheet index and match
A1: index | B1: Get Value based on cell Location
A2: match | B2: Get cell location based on Value | C2: we can choose only row or column
A3: X match | B3: Additional Configuration with Match
C4: Formula
E5: 1 | F5: 2 | G5: 3 | H5: 4 | I5: 5
A6: index | B6: =INDEX(E6:I8,3,3) -> i | C6: INDEX(E6:I8,3,3) | D6: 1 | E6: a | F6: b | G6: c | H6: a | I6: b
A7: row | B7: =INDEX(E6:I6,1,3) -> c | C7: INDEX(E6:I6,1,3) | D7: 2 | E7: d | F7: e | G7: f | H7: d | I7: e
B8: =INDEX(E6:E8,1,1) -> a | C8: INDEX(E6:E8,1,1) | D8: 3 | E8: g | F8: h | G8: i | H8: g | I8: h
A10: Match | B10: =MATCH("f",E7:I7,0) -> 3 | C10: MATCH("f",E7:I7,0)
B11: =MATCH("f",G6:G8,0) -> 2 | C11: MATCH("f",G6:G8,0)
A14: xmatch | B14: =_xlfn.XMATCH("d",E7:I7,0,-1) -> 4 | C14: XMATCH("d",E7:I7,0,-1)
A16: EG: | B16: course | E16: registration
A17: Data science | B17: 60000 | C17: 6 | E17: Student Name | F17: Manoj
A18: Data Analytics | B18: 45000 | C18: 5 | E18: Choose Course | F18: Python
A19: BA | B19: 50000 | C19: 5 | E19: Price | F19: =INDEX(B17:B20,MATCH(F18,A17:A20,0)) -> 35000 | I19: MATCH(F18,A17:A20,0)
A20: Python | B20: 35000 | C20: 3 | E20: Duration | F20: =INDEX(C17:C20,MATCH(F18,A17:A20,0)) -> 3

Sheet Sheet1
A2: Region-wise total Revenue
A3: Row Labels | B3: Sum of Revenue
A4: East | B4: 606400
A5: North | B5: 571400
A6: South | B6: 487000
A7: West | B7: 461600
A8: Grand Total | B8: 2126400
A9: Salesperson | B9: (All)
A10: Product-wise total Quantity sold
A11: Row Labels | B11: Count of Order_ID
A12: Headset | B12: 8
A13: Keyboard | B13: 8
A14: Laptop | B14: 9
A15: Monitor | B15: 8
A16: Mouse | B16: 9
A17: Printer | B17: 8
A18: Grand Total | B18: 50
A20: Sum of Revenue | B20: Column Labels
A21: Row Labels | B21: East | C21: North | D21: South | E21: West | F21: Grand Total
A22: Arun | B22: 187000 | C22: 311000 | D22: 206000 | E22: 200000 | F22: 904000
A23: Divya | B23: 37000 | C23: 79900 | D23: 17500 | E23: 91100 | F23: 225500
A24: Karthik | B24: 282500 | C24: 144000 | D24: 170000 | E24: 139000 | F24: 735500
A25: Priya | B25: 99900 | C25: 36500 | D25: 93500 | E25: 31500 | F25: 261400
A26: Grand Total | B26: 606400 | C26: 571400 | D26: 487000 | E26: 461600 | F26: 2126400
A28: Sum of Revenue | B28: Column Labels
A29: Row Labels | B29: Karthik | C29: Grand Total
A30: North | B30: 144000 | C30: 144000
A31: Printer | B31: 144000 | C31: 144000
A32: West | B32: 84000 | C32: 84000
A33: Monitor | B33: 84000 | C33: 84000
A34: Grand Total | B34: 228000 | C34: 228000

Sheet Pivot
A1: Order_ID | B1: Date | C1: Salesperson | D1: Region | E1: Product | F1: Category | G1: Quantity | H1: Unit_Price | I1: Revenue | J1: Payment_Mode | M1: Region-wise total Revenue
A2: ORD001 | B2: 46027 | C2: Arun | D2: North | E2: Laptop | F2: Electronics | G2: 2 | H2: 55000 | I2: 110000 | J2: Card | M2: Salesperson-wise total Revenue
A3: ORD002 | B3: 46028 | C3: Priya | D3: South | E3: Mouse | F3: Accessories | G3: 10 | H3: 800 | I3: 8000 | J3: UPI | M3: Product-wise total Quantity sold
A4: ORD003 | B4: 46029 | C4: Karthik | D4: East | E4: Keyboard | F4: Accessories | G4: 5 | H4: 1500 | I4: 7500 | J4: Cash | M4: Product-wise total Revenue
A5: ORD004 | B5: 46030 | C5: Divya | D5: West | E5: Monitor | F5: Electronics | G5: 3 | H5: 12000 | I5: 36000 | J5: Card | M5: Category-wise Revenue
A6: ORD005 | B6: 46031 | C6: Arun | D6: South | E6: Printer | F6: Electronics | G6: 2 | H6: 18000 | I6: 36000 | J6: UPI | M6: Region-wise Average Revenue
A7: ORD006 | B7: 46032 | C7: Priya | D7: North | E7: Headset | F7: Accessories | G7: 8 | H7: 2500 | I7: 20000 | J7: Card | M7: Payment Mode-wise total Revenue
A8: ORD007 | B8: 46033 | C8: Karthik | D8: West | E8: Laptop | F8: Electronics | G8: 1 | H8: 55000 | I8: 55000 | J8: UPI | M8: Salesperson + Region → Total Revenue
A9: ORD008 | B9: 46034 | C9: Divya | D9: East | E9: Mouse | F9: Accessories | G9: 15 | H9: 800 | I9: 12000 | J9: Cash | M9: Region + Product → Total Quantity
A10: ORD009 | B10: 46035 | C10: Arun | D10: East | E10: Monitor | F10: Electronics | G10: 4 | H10: 12000 | I10: 48000 | J10: Card | M10: Salesperson + Product → Total Revenue
A11: ORD010 | B11: 46036 | C11: Priya | D11: South | E11: Keyboard | F11: Accessories | G11: 7 | H11: 1500 | I11: 10500 | J11: UPI | M11: Find which product generated the highest Revenue
A12: ORD011 | B12: 46037 | C12: Karthik | D12: North | E12: Printer | F12: Electronics | G12: 3 | H12: 18000 | I12: 54000 | J12: Card | M12: Find which Region generated the highest Revenue
A13: ORD012 | B13: 46038 | C13: Divya | D13: West | E13: Headset | F13: Accessories | G13: 6 | H13: 2500 | I13: 15000 | J13: Cash | M13: Find which Salesperson handled the highest number of Orders
... A15: ORD014 | B15: 46040 | C15: Priya | D15: East | E15: Mouse | F15: Accessories | G15: 20 | H15: 800 | I15: 16000 | J15: Card | M15: Show Salesperson in Rows, Payment Mode in Columns, Revenue in Values
A16: ORD015 | B16: 46041 | C16: Karthik | D16: South | E16: Monitor | F16: Electronics | G16: 2 | H16: 12000 | I16: 24000 | J16: Cash
A17: ORD016 | B17: 46042 | C17: Divya | D17: North | E17: Keyboard | F17: Accessories | G17: 10 | H17: 1500 | I17: 15000 | J17: UPI
A18: ORD017 | B18: 46043 | C18: Arun | D18: West | E18: Printer | F18: Electronics | G18: 1 | H18: 18000 | I18: 18000 | J18: Card
A19: ORD018 | B19: 46044 | C19: Priya | D19: South | E19: Headset | F19: Accessories | G19: 12 | H19: 2500 | I19: 30000 | J19: UPI
A20: ORD019 | B20: 46045 | C20: Karthik | D20: East | E20: Laptop | F20: Electronics | G20: 2 | H20: 55000 | I20: 110000 | J20: Card
A21: ORD020 | B21: 46046 | C21: Divya | D21: North | E21: Mouse | F21: Accessories | G21: 18 | H21: 800 | I21: 14400 | J21: Cash
A22: ORD021 | B22: 46047 | C22: Arun | D22: South | E22: Monitor | F22: Electronics | G22: 5 | H22: 12000 | I22: 60000 | J22: UPI
A23: ORD022 | B23: 46048 | C23: Priya | D23: West | E23: Keyboard | F23: Accessories | G23: 9 | H23: 1500 | I23: 13500 | J23: Card
A24: ORD023 | B24: 46049 | C24: Karthik | D24: North | E24: Printer | F24: Electronics | G24: 2 | H24: 18000 | I24: 36000 | J24: Cash
A25: ORD024 | B25: 46050 | C25: Divya | D25: East | E25: Headset | F25: Accessories | G25: 10 | H25: 2500 | I25: 25000 | J25: UPI
A26: ORD025 | B26: 46051 | C26: Arun | D26: East | E26: Laptop | F26: Electronics | G26: 1 | H26: 55000 | I26: 55000 | J26: Card
A27: ORD026 | B27: 46052 | C27: Priya | D27: South | E27: Mouse | F27: Accessories | G27: 25 | H27: 800 | I27: 20000 | J27: UPI
... A51: ORD050 | B51: 46076 | C51: Priya | D51: East | E51: Mouse | F51: Accessories | G51: 28 | H51: 800 | I51: 22400 | J51: UPI

Sheet data validation
A1: Python | B1: 35000
A2: PHP | B2: 3000
A3: Java | B3: 232
A4: Data Analytics | B4: 234
A5: Data Engineer | B5: 545 | E5: Student Name
E6: Course | F6: PHP
E7: Fees

Sheet filter
A1: Logical Operator | D1: FILTER(A2:G6,C2:C6>20)
A2: * | B2: and | D2: FILTER(G:G,ISNUMBER(SEARCH("ram",G:G)))
A3: + | B3: or | D3: FILTER(A2:G6,(G2:G6="Cuddalore")+(G2:G6="Panruti"))
D4: FILTER(A2:G6,(G2:G6="Chidambaram")*(C2:C6>18))
D5: FILTER(A2:G6,(C2:C6>=18)*(C2:C6<=25))
D6: FILTER(A2:G6,E2:E6<=DATE(2022,2,20))
D7: FILTER(A2:G6,D2:D6>=DATE(2022,1,15))
D8: FILTER(A2:G6,F2:F6="Beach Road")
D9: FILTER(A2:G6,(G2:G6="Chidambaram")+(G2:G6="Pondicherry"))
D10: FILTER(A2:G6,(C2:C6>18)*(G2:G6="Chidambaram"))
D11: FILTER(A2:G6,G2:G6="Chidambaram")

Sheet link
A1: Linkedin
A2: Monisha

Sheet text
A1: mobile | B1: Code | C1: Number
A2: +91-8989889989 | B2: =LEFT(A2,3) -> +91 | C2: =RIGHT(A2,10) -> 8989889989 | F2: MID(A10,5,1)
A3: +91-8989889989 | B3: =LEFT(A3,3) -> +91 | C3: =RIGHT(A3,10) -> 8989889989 | F3: RIGHT(A2,10)
A4: +91-8989889989 | B4: =LEFT(A4,3) -> +91 | C4: =RIGHT(A4,10) -> 8989889989 | F4: LEFT(A2,3)
A5: +91-8989889989 | B5: =LEFT(A5,3) -> +91 | C5: =RIGHT(A5,10) -> 8989889989
A6: +91-8989889989 | B6: =LEFT(A6,3) -> +91 | C6: =RIGHT(A6,10) -> 8989889989
A7: +91-8989889989 | B7: =LEFT(A7,3) -> +91 | C7: =RIGHT(A7,10) -> 8989889989
A9: EmployeeCode
A10: 2024E001 | B10: =MID(A10,5,1) -> E
A11: 2024SS0001 | B11: =MID(A11,5,2) -> SS
A13: text before | C13: Sundar Lingam | D13: =_xlfn.TEXTBEFORE(C13," ",) -> Sundar | F13: =_xlfn.TEXTBEFORE(C13," ") -> Sundar
A14: textAfter | D14: =_xlfn.TEXTAFTER(C13," ",) -> Lingam
A16: options | B16: Sundar Lingam Chennai
A17: use instance number | B17: =_xlfn.TEXTAFTER(B16," ") -> Lingam Chennai | F17: =_xlfn.TEXTAFTER(B16," ") -> Lingam Chennai | G17: =_xlfn.TEXTAFTER(B16," ",2) -> Chennai
A18: match end if not found | B18: =_xlfn.TEXTAFTER(B16," ",2) -> Chennai
A19: if not found | B19: =_xlfn.TEXTAFTER(B16,",") -> #N/A | C19: =_xlfn.TEXTAFTER(B16,",",,,,"no") -> no
A21: split text into Columns
A22: Data science,python,django | B22: {=_xlfn.TEXTSPLIT(A22,",")} -> Data science | C22: python | D22: django | F22: {=_xlfn.TEXTSPLIT(A22,",")} -> Data science | G22: python | H22: django
A23: Data science | B23: {=_xlfn.TEXTSPLIT(A23,",")} -> Data science | F23: {=_xlfn.TEXTSPLIT(A23,",")} -> Data science
A26: column and row
A27: Data science,python,django|SQL ,postgress|pandas,seaborn | B27: {=_xlfn.TEXTSPLIT(A27,",","|")} -> Data science | C27: python | D27: django | F27: {=_xlfn.TEXTSPLIT(A27,",","|")} -> Data science | G27: python | H27: django | J27: {=_xlfn.TEXTSPLIT(A27,,"|")} -> Data science,python,django
B28: SQL | C28: postgress | D28: #N/A | F28: SQL | G28: postgress | H28: #N/A | J28: SQL ,postgress
B29: pandas | C29: seaborn | D29: #N/A | F29: pandas | G29: seaborn | H29: #N/A | J29: pandas,seaborn
A32: ignore or Keep Empty Value
A33: Data science,,python,django | B33: {=_xlfn.TEXTSPLIT(A33,",")} -> Data science | D33: python | E33: django
A34: Data science,,python,django | B34: {=_xlfn.TEXTSPLIT(A34,",",,TRUE)} -> Data science | C34: python | D34: django
A37: Search
A38: Find | B38: find the Position of given text/char withiin the content
A39: Search | B39: ignores case sensitive and find the position
A40: length | B40: size of the given text content
A42: Example:
A43: Find | B43: Content | C43: Find | D43: Search | E43: Length | F43: =FIND(A44,B44) -> 11
A44: brown | B44: the quick brown fox jumped over the lazy dog | C44: =FIND(A44,B44) -> 11 | D44: =SEARCH(A44,B44) -> 11 | E44: =LEN(B44) -> 44 | G44: =FIND(A44,B44) -> 11
A45: Brown | B45: the quick brown fox jumped over the lazy dog | C45: =FIND(A45,B45) -> #VALUE! | D45: =SEARCH(A45,B45) -> 11 | E45: =LEN(B45) -> 44
A46: the | B46: The quick brown fox jumped over the lazy dog | C46: =FIND(A46,B46) -> 33 | D46: =SEARCH(A46,B46) -> 1
A48: 1 | B48: Concatenate | C48: Joining text values from cells or strings | D48: Sundar | E48: Lingam | F48: =CONCATENATE(D48," ",E48,D48) -> Sundar LingamSundar | H48: =CONCATENATE(D48," ",E48,F48,B48) -> Sundar LingamSundar LingamSundarConcatenate
A49: 2 | B49: concat(Range select panrapa space add pana mudiyathu) | C49: joining text calues but also support range of cells | D49: Sundar | E49: Lingam | F49: =_xlfn.CONCAT(D49," ",E49) -> Sundar Lingam | H49: =_xlfn.CONCAT(D49:F49) -> SundarLingamSundar Lingam
A50: 3 | B50: text join | C50: joining text values with additional suports of delimiter | D50: Sundar | E50: Lingam | F50: =_xlfn.TEXTJOIN(" ",TRUE,E50,D50) -> Lingam Sundar
A51: 4 | B51: (&) | C51: directly | D51: Sundar | E51: Lingam | F51: =D51&E51 -> SundarLingam | G51: =E51&" "&D51 -> Lingam Sundar
C53: =CONCATENATE(D48," ",E48) -> Sundar Lingam | E53: =CONCATENATE(E48," ",D48) -> Lingam Sundar
...

Sheet datetime
A1: Date time | C1: Formula | D1: Example
A2: date | B2: Creates a valid date from separate year,month and days | C2: DATE(year,month,day) | D2: =DATE(2026,9,25) -> 46290 | J2: 45910
A3: Time | B3: Creates a time value from parts | C3: TIME(hr,min,sec) | D3: =TIME(6,9,15) -> 0.25642361 | E3: Rallway time | F3: =TIME(21,20,10) -> 0.88900463 | G3: TIME(21,20,10)
A4: datetime | B4: combine date + time to create Date time | C4: DATE(2026,9,1)+TIME(1,45,34) | D4: =DATE(2026,9,1)+TIME(1,45,34) -> 46266.073 | E4: change format with custom
A5: today | B5: return the current system date | C5: today() | D5: =TODAY() -> 46309
A6: now | B6: current date and time | C6: now() | D6: =NOW() -> 46309.696
A8: Date time conversion
A10: date | B10: date text to date | C10: 44996 | D10: =DATEVALUE(C10) -> #VALUE! | F10: DATEVALUE(C10)
A11: time | B11: time text to date | C11: 0.72916667 | D11: =TIMEVALUE(C11) -> #VALUE! | E11: =MIN(C11) -> 0.72916667
A13: extract | B13: day(serial_number) | C13: 44996 | D13: =DAY(C13) -> 11 | F13: =DAY(C13) -> 11
B14: month(serial_number) | D14: =MONTH(C13) -> 3 | F14: =MONTH(C13) -> 3
B15: year(serial_number) | D15: =YEAR(C13) -> 2023 | H15: =YEAR(C13) -> 2023
B16: hour(serial_number)
B17: minute(serial_number) | C17: =WEEKNUM(C13,1) -> 10 | D17: =WEEKDAY(C10,2) -> 6 | F17: =WEEKDAY(C13,2) -> 6
B18: seconds(serial_number)
B19: weeknum(serial_number,return_type)
B20: weekday(serial_number,return_type)
A22: Date Difference | C22: Date1 | D22: date2
A23: Date Dif | B23: in years | C23: 46290 | D23: 46675 | E23: =DATEDIF(C23,D23,"Y") -> 1 | F23: datedif(date1,date2,"Y") | J23: =DATEDIF(C23,D23,"d") -> 385
B24: in months | C24: 46290 | D24: 46371 | E24: =DATEDIF(C24,D24,"m") -> 2 | F24: datedif(date1,date2,"m")
B25: in days | C25: 46290 | D25: 46310 | E25: =DATEDIF(C25,D25,"d") -> 20 | F25: datedif(date1,date2,"d")
A26: Days | B26: no of days between 2 dates | C26: 46290 | D26: 46310 | E26: =_xlfn.DAYS(D26,C26) -> 20 | F26: days(end_date,start_date)
A27: net work days | B27: working days between two dates | C27: 46290 | D27: 46310 | E27: =NETWORKDAYS(C27,D27) -> 15 | F27: NETWORKDAYS(C27,D27)
B28: include holiday | C28: 46290 | D28: 46310 | E28: =_xlfn.NETWORKDAYS.INTL(C28,D28,11) -> 18 | F28: NETWORKDAYS(start_date,end_date,holiday list)
A29: network days,intl | B29: Optionally configuring weekends | C29: 46290 | D29: 46310
A30: year fraction | B30: calculate fractional year between 2 dates | C30: 46290 | D30: 46310 | E30: =YEARFRAC(C30,D30) -> 0.055555556
A32: Date addition/adjustments
A33: edate | B33: EDATE(C33,3) | C33: 46290 | D33: =EDATE(C33,3) -> 46381 | E33: =EDATE(D33,-3) -> 46290 | G33: =EDATE(C33,5) -> 46443 | H33: =EDATE(C33,-5) -> 46137
A34: 0 | B34: EOMONTH(C33,3) | C34: =EOMONTH(C33,3) -> 46387
B35: WORKDAY(C33,5) | C35: =WORKDAY(C33,5) -> 46297
